Workbook

Sheet PRECIOS
A1: CUBANITOS
B2: COMUNES | C2: BAÑADOS | D2: TOTAL
A3: 1 | B3: 900 | C3: 1200 | D3: =SUM(B3+C3) -> 2100
A4: 2 | B4: =+B3+900 -> 1800 | C4: =+C3+1200 -> 2400 | D4: =+B4+C4 -> 4200
A5: 3 | B5: =+B4+900 -> 2700 | C5: =+C4+1200 -> 3600 | D5: =+B5+C5 -> 6300
A6: 4 | B6: =+B5+900 -> 3600 | C6: =+C5+1200 -> 4800 | D6: =+B6+C6 -> 8400
A7: 5 | B7: =+B6+900 -> 4500 | C7: =+C6+1200 -> 6000 | D7: =+B7+C7 -> 10500
A8: 6 | B8: =+B7+900 -> 5400 | C8: =+C7+1200 -> 7200 | D8: =+B8+C8 -> 12600
A9: 7 | B9: =+B8+900 -> 6300 | C9: =+C8+1200 -> 8400 | D9: =+B9+C9 -> 14700
A10: 8 | B10: =+B9+900 -> 7200 | C10: =+C9+1200 -> 9600 | D10: =+B10+C10 -> 16800
A11: 9 | B11: =+B10+900 -> 8100 | C11: =+C10+1200 -> 10800 | D11: =+B11+C11 -> 18900
A12: 10 | B12: =+B11+900 -> 9000 | C12: =+C11+1200 -> 12000 | D12: =+B12+C12 -> 21000
A13: 11 | B13: =+B12+900 -> 9900 | C13: =+C12+1200 -> 13200 | D13: =+B13+C13 -> 23100
A14: 12 | B14: =+B13+900 -> 10800 | C14: =+C13+1200 -> 14400 | D14: =+B14+C14 -> 25200
A15: 13 | B15: =+B14+900 -> 11700 | C15: =+C14+1200 -> 15600 | D15: =+B15+C15 -> 27300
... A26: 24 | B26: =+B25+900 -> 21600 | C26: =+C25+1200 -> 28800 | D26: =+B26+C26 -> 50400

Sheet VENTAS JULIO
A1: MES:
B2: CUBANITOS | E2: METODO DE PAGO | G2: TOTAL | I2: MES JULIO
A3: DIA | B3: COMUNES | C3: BAÑADOS | D3: OTRO | E3: EFECTIVO | F3: TRANSFERENCIA | G3: VENTAS $
A4: 45854 | B4: =12+7+4 -> 23 | C4: =12+5+6+8 -> 31 | D4: 5 | E4: 25300 | F4: 37500 | G4: =E4+F4 -> 62800 | I4: Tranferencia | J4: =SUMIF(F4:F21,">0") -> 718400
A5: 45855 | B5: 15 | C5: 12 | D5: 3 | E5: 15000 | F5: 17700 | G5: =E5+F5 -> 32700 | I5: efectivo | J5: =SUMIF(E4:E21,">0") -> 871000
A6: 45856 | B6: =10+8+6+6+12 -> 42 | C6: =16+12 -> 28 | D6: 1 | E6: 46000 | F6: 21000 | G6: =E6+F6 -> 67000 | I6: TOTAL | J6: =J4+J5 -> 1589400
A7: 45857 | B7: =24+4+2+6+4+2+12+6+4+1+12+4 -> 81 | C7: =4+2+12+4+2+6+2+2+6+2+5+6+1+12+6 -> 72 | D7: 4 | E7: =4800+4400+4200+13600+4200+7000 -> 38200 | F7: =21600+14400+8400+6000+10800+12600+6900+7200+1200+25200+10800-600 -> 124500 | G7: =E7+F7 -> 162700 | I7: CONSUMO CUBANITOS
A8: 45858 | B8: =4+2+3+4+5+8+6+5+4+4+4+8+6+12+6+12+6+12+7+2 -> 120 | C8: =4+1+6+4+6+5+8+4+6+4+2+8+4+1+6+3 -> 72 | D8: 10 | E8: =9900+7200+9600+12000+9300+8400+6600+18000+5400+10800+6300+2800 -> 106300 | F8: =8400+1000+3000+9400+10500+12600+8000+13200+9100+9000+12800 -> 97000 | G8: =E8+F8 -> 203300 | I8: COMUNES | J8: BAÑADOS
A9: 45859 | B9: =3+4+1+4+6+4+8+6 -> 36 | C9: =1+6+8+2+1+6+12 -> 36 | D9: 1 | E9: =3900+7200+13200+5400+4600+7200+12600+14400 -> 68500 | F9: =3300+4800 -> 8100 | G9: =E9+F9 -> 76600 | I9: =SUM(B4:B20) -> 887 | J9: =SUM(C4:C20) -> 625
A10: 45860 | B10: =2+6+2+6+10+3+2+6+6+12+4+6+2+6 -> 73 | C10: =2+6+2+4+6+3+12+6+2+2+6 -> 51 | D10: 5 | E10: =4200+12600+6600+12600+9000+1800+5400+21800+4200+14600 -> 92800 | F10: =2400+6300+18000+7000+5400 -> 39100 | G10: =E10+F10 -> 131900
A11: 45861 | B11: =6+8+6+6+12+4+6+3+4+4 -> 59 | C11: =6+6+2+6+3+4+4 -> 31 | D11: =1+1 -> 2 | E11: =12600+7200+1000+6000+8400+8400 -> 43600 | F11: =5400+12600+11800+12600+6300+7200 -> 55900 | G11: =E11+F11 -> 99500
A12: 45862 | B12: =6+6+2 -> 14 | C12: =6+6+10+6 -> 28 | D12: 0 | E12: =5400+13700+7200 -> 26300 | F12: =7200+12600+100 -> 19900 | G12: =E12+F12 -> 46200
A13: 45863 | B13: =6+4+12+4+4+5+6+4+6+6 -> 57 | C13: =4+4+4+8 -> 20 | D13: =1+1+1 -> 3 | E13: =5400+8400+11800+3600+10300+5400+5400+5400+1000 -> 56700 | F13: =8400+14200 -> 22600 | G13: =E13+F13 -> 79300
A14: 45864 | B14: =12+2+7+2+22+11+6+3+12+2+3+8+10+4+4+6+6+6 -> 126 | C14: =3+4+8+2+4+2+1+4+4+2+6+2+4+6+6+6 -> 64 | D14: =1+1+1 -> 3 | E14: =14400+9600+9000+6600+11100+5400+2700+15600+5100+8200+8400+12600+12600+5400+7200 -> 133900 | F14: =7600+1000+1200+22000+6600+16200+6000 -> 60600 | G14: =E14+F14 -> 194500
A15: 45865 | B15: =6+3+6+6+6+3+8+4+8+12+6+6+7+3+8+6 -> 98 | C15: =6+2+6+2+3+8+4+2+12+3+6+1+9 -> 64 | D15: 1 | E15: =2700+8800+5400+6300+6000+7200+10800+5400+3600+7500+8100+5400 -> 77200 | F15: =12600+5400+1200+9600+12000+14400+12600+13500 -> 81300 | G15: =E15+F15 -> 158500
A16: 45866 | B16: =12+4+6+4+12+2 -> 40 | C16: =6+5+6 -> 17 | D16: 1 | E16: =18000+9600+10800+1700 -> 40100 | F16: =13600+3600 -> 17200 | G16: =E16+F16 -> 57300
A17: 45867 | B17: =4+6 -> 10 | C17: =8+6+5+12 -> 31 | D17: 1 | E17: =1000+3600+7200+6000+19800 -> 37600 | F17: 9600 | G17: =E17+F17 -> 47200
A18: 45868 | B18: =2+6+7+12+3+2+6 -> 38 | C18: =2+6+6+3+3 -> 20 | D18: 2 | E18: =4800+6300+10800+5400 -> 27300 | F18: =7200+12600+8300+5400 -> 33500 | G18: =E18+F18 -> 60800
A19: 45869 | B19: =6+5+6+6+6+6+3+2+8+1+6 -> 55 | C19: =5+4+4+6+5+12+6+3+2+1 -> 48 | D19: 2 | E19: =10500+6800+5400+6300+1800+5400 -> 36200 | F19: =5400+4800+12600+6000+19800+12600+2400+7200+2100 -> 72900 | G19: =E19+F19 -> 109100
A20: 45870
A21: 45871
A22: 45872
A23: 45873
A24: 45874
A25: 45875
A26: 45876
A27: 45877
A28: 45878
A29: 45879

Sheet GASTOS JULIO
A1: DETALLES GASTOS ENTREGADOS POR CONTRATISTA, FACTURAS "A"
K2: PAGOS
A3: FECHA | B3: ABONO | C3: RUBRO | D3: PROVEEDOR | E3: CANTIDAD | F3: DESCRIPCIÓN | G3: $ c/IVA+Ing.Br | H3: IVA | I3: 1/2IVA | J3: Perc.Ing.Bruto | K3: EFECTIVO | L3: TRANFERENCIA
A5: 45823 | B5: E | C5: HERRAJE | D5: FEDE VALENTE | F5: RUEDASN+ GUIAS PARA VENTA | G5: 17500 | K5: 17500
A6: 45823 | B6: E | C6: SELLADORES | D6: PROMAR | F6: FASTIC+ CINTA BURLETE | G6: 66900 | K6: 66900
A7: 45823 | B7: E | C7: IMPUESTO | D7: ARCA | F7: MONOTRIBUTO MES JUNIO | G7: 10143.98 | K7: 10143.98
A8: 45823 | B8: E | C8: PLAGAS | D8: LUGONES | F8: CONTROL DE PLGAS MES JUNIO | G8: 16000 | K8: 16000
A9: 45823 | B9: M | C9: IMPUESTO | D9: MUNICIPALIDAD | F9: TASA DE SEGURIDAD E HIGIENE + HABILITACION | G9: 31717 | K9: 31717
A10: 45823 | B10: E | C10: GARRAFA | D10: GARRAFA DON BOSCO | F10: CARGA DE GARRAFA | G10: 6600 | K10: 6600
A11: 45823 | B11: E | C11: BOLSAS | D11: MICRO ENVASES | F11: 1 00 GUANTES +200 BOLSAS N3+ 200 BOLSAS N4+ BOLSA CAMISETA | G11: 8200 | K11: 8200
A12: 45823 | B12: M | C12: ACRILICO | D12: ACRILICO | F12: ACRILICOS PARA VENTANA | G12: 124000 | K12: 124000
A13: 45823 | B13: M | C13: PLOTEO | D13: VICTOR | F13: PLOTEO CARRO | G13: 140000 | K13: 140000
A15: 45854 | B15: M | C15: CUBANITO COMUN | D15: MAXI | E15: 400 | F15: 1 CAJA X 400 CUBANITOS COMUNES ($156,00 X UNIDAD) | G15: =156*400 -> 62400
A16: 45854 | B16: M | C16: CUBANITO BAÑADO | D16: MAXI | E16: 300 | F16: 1 CAJA X 300 CUBANITOS BAÑADOS ($333,00 X UNIDAD) | G16: =333*300 -> 99900
A17: 45854 | B17: M | C17: DULCE DE LECHE | D17: MAXI | E17: 1 | F17: 1 POTE X 10KG DULCE DE LECHE LUZ AZUL | G17: 41032 | K17: =SUM(G15:G17) -> 203332
A18: 45853 | B18: M | C18: GARRAPIÑADA | D18: SEÑORA | E18: 3 | F18: 3 KG DE GARRAPIÑADA ($7.000 X KG) | G18: 21000 | K18: =+G18 -> 21000
A19: 45855 | B19: C | C19: CONTADOR | D19: JORGE | F19: PAGO INICIO ACTIVIDAD JORGE | G19: 20000 | L19: 20000
A20: 45855 | B20: C | C20: IMPUESTO | D20: MUNICIPALIDAD | F20: TASA SEGURIDAD E HIGIENE JULIO 2025 | G20: 13700 | L20: 13700
A21: 45856 | B21: C | C21: DULCE DE LECHE | D21: JULIA | E21: 1 | F21: 1 POTE X 10KG DULCE DE LECHE PIGUENSE | G21: 25000 | K21: 25000
A22: 45859 | B22: C | C22: PLAGAS | D22: LUGONES | F22: CONTROL DE PLGAS MES JULIO | G22: 16000 | K22: 16000
A23: 45859 | B23: C | C23: IMPUESTO | D23: ARCA | F23: MONOTRIBUTO MES JULIO | G23: 10143.98 | L23: 10143.98
A24: 45863 | B24: C | C24: CUBANITO COMUN | D24: MAXI | E24: 200 | F24: 1 CAJA X 200 CUBANITOS COMUNES ($156,00 X UNIDAD) | G24: =156*200 -> 31200
A25: 45863 | B25: C | C25: CUBANITO BAÑADO | D25: MAXI | E25: 400 | F25: 1 CAJA X 400 CUBANITOS BAÑADOS ($333,00 X UNIDAD) | G25: =333*400 -> 133200
A26: 45863 | B26: C | C26: DULCE DE LECHE | D26: MAXI | E26: 1 | F26: 1 POTE X 10KG DULCE DE LECHE PIGUENSE | G26: 22500 | K26: =SUM(G24:G26) -> 186900
A27: 45860 | B27: C | C27: DULCE DE LECHE | D27: JULIA | E27: 2 | F27: 2 POTE X 10KG DULCE DE LECHE PIGUENSE | G27: =2*25000 -> 50000 | K27: 50000
A28: 45862 | B28: C | C28: MOVIMIENTO | D28: CARRO | F28: TRANFERENCIA PARA GENERAR EFECTIVO | G28: 100000 | K28: -100000 | L28: 100000
A29: 45863 | B29: C | C29: GARRAPIÑADA | D29: GLORIA | E29: 5 | F29: 5 KG DE GARRAPIÑADA ($7.000 X KG) | G29: =7000*5 -> 35000 | K29: =+G29 -> 35000
A30: 45863 | B30: C | C30: CUBANITO COMUN | D30: MAXI | E30: 200 | F30: 1 CAJA X 200 CUBANITOS COMUNES ($156,00 X UNIDAD) | G30: =156*200 -> 31200
A31: 45863 | B31: C | C31: CUBANITO BAÑADO | D31: MAXI | E31: 200 | F31: 1 CAJA X 200 CUBANITOS BAÑADOS ($333,00 X UNIDAD) | G31: =333*200 -> 66600 | K31: =G30+G31 -> 97800
A32: 45866 | B32: C | C32: CUBANITO COMUN | D32: MAXI | E32: 400 | F32: 1 CAJA X 400 CUBANITOS COMUNES ($156,00 X UNIDAD) | G32: =156*400 -> 62400
A33: 45866 | B33: C | C33: DULCE DE LECHE | D33: MAXI | E33: 1 | F33: 1 POTE X 10KG DULCE DE LECHE PIGUENSE | G33: 22500 | K33: =SUM(G32:J33) -> 84900
A34: 45869 | B34: C | C34: EXTRACCION | D34: ERICA | F34: EXTRACCION MES JULIO EFECTIVO | G34: 200000 | K34: 200000 | L34: 0
A35: 45869 | B35: C | C35: EXTRACCION | D35: MATIAS | F35: EXTRACCION MES JULIO BANCARIZADA X TRANFERENCIAS | G35: 200000 | K35: 0 | L35: 200000
H37: =+(G37-J37)-(G37-J37)/1.21 -> 0
A38: INSERTAR FILAS ANTES QUE ESTA
F42: TOTAL FACTURAS | G42: =SUM(G14:G41) -> 1263776 | H42: =SUM(H14:H41) -> 0 | I42: =SUM(I14:I41) -> 0 | J42: =SUM(J14:J40) -> 0 | K42: =SUM(K15:K41) -> 819932 | L42: =SUM(L4:L40) -> 343843.98
H45: =+H42/0.105 -> 0 | I45: =+I42/0.105 -> 0

Sheet GASTOS AGOSTO
A1: DETALLES GASTOS ENTREGADOS POR CONTRATISTA, FACTURAS "A"
K2: PAGOS
A3: FECHA | B3: ABONO | C3: RUBRO | D3: PROVEEDOR | E3: CANTIDAD | F3: DESCRIPCIÓN | G3: $ c/IVA+Ing.Br | H3: IVA | I3: 1/2IVA | J3: Perc.Ing.Bruto | K3: EFECTIVO | L3: TRANFERENCIA
A4: 45870 | B4: C | C4: GARRAFA | D4: CASA DON BOSCO | F4: CARGA DE GARRAFA | G4: 6000 | K4: 6000
A5: 45873 | B5: C | C5: CUBANITO BAÑADO | D5: MAXI | E5: 200 | F5: 1 CAJA X 200 CUBANITOS BAÑADOS ($333,00 X UNIDAD) | G5: =333*200 -> 66600
A6: 45873 | B6: C | C6: DULCE DE LECHE | D6: MAXI | E6: 1 | F6: 1 POTE X 10KG DULCE DE LECHE PIGUENSE | G6: 25600 | K6: =G5+G6 -> 92200
A7: 45873 | B7: C | C7: CUBANITO COMUN | D7: MAXI | E7: 200 | F7: 1 CAJA X 200 CUBANITOS COMUNES ($156,00 X UNIDAD) | G7: =156*200 -> 31200
A8: 45873 | B8: C | C8: CUBANITO BAÑADO | D8: MAXI | E8: 200 | F8: 1 CAJA X 200 CUBANITOS BAÑADOS ($333,00 X UNIDAD) | G8: =333*200 -> 66600
A9: 45873 | B9: C | C9: DULCE DE LECHE | D9: MAXI | E9: 1 | F9: 1 POTE X 10KG DULCE DE LECHE PIGUENSE | G9: 25500 | K9: =G7+G8+G9 -> 123300
A10: 45874 | B10: C | C10: CERRAJERIA | D10: CERRAJERIA | E10: 1 | F10: LLAVE CARRO | G10: 5000 | K10: 5000
A11: 45880 | B11: C | C11: IMPUESTO | D11: ARCA | F11: MONOTRIBUTO MES AGOSTO | G11: 11677.6 | L11: =G11 -> 11677.6
A12: 45883 | B12: C | C12: CUBANITO COMUN | D12: MAXI | E12: 400 | F12: 1 CAJA X 400 CUBANITOS COMUNES ($156,00 X UNIDAD) | G12: =156*400 -> 62400
A13: 45883 | B13: C | C13: CUBANITO BAÑADO | D13: MAXI | E13: 400 | F13: 1 CAJA X 400 CUBANITOS BAÑADOS ($333,00 X UNIDAD) | G13: 133200
A14: 45883 | B14: C | C14: DULCE DE LECHE | D14: MAXI | E14: 4 | F14: 4 POTE X 10KG DULCE DE LECHE LUZ AZUL | G14: =82064+82064 -> 164128
A15: 45883 | B15: C | C15: REDONDEO | D15: MAXI | E15: 0 | F15: REDONDEO | G15: 272 | K15: =G12+G13+G14+G15 -> 360000
A16: 45883 | B16: C | C16: BOLSAS | D16: MICRO ENVASES | E16: 1000 | F16: 500 BOLSAS N3+ 500 BOLSAS N4 | G16: 23750 | K16: 23750
A17: 45883 | B17: C | C17: BOLSAS | D17: MICRO ENVASES | E17: 1 | F17: 200 GUANTES+ BOLSAS CAMISETAS | G17: 3800 | K17: 3800
A18: 45884 | B18: C | C18: EXTRACCION | D18: ERICA | F18: EXTRACCION MES AGOSTO EFECTIVO | G18: =K18+L18 -> 427000 | K18: 150000 | L18: 277000
A19: 45884 | B19: C | C19: EXTRACCION | D19: MATIAS | F19: EXTRACCION MES AGOSTO BANCARIZADA X TRANFERENCIAS | G19: =K19+L19 -> 427000 | K19: 150000 | L19: 277000
A20: 45870 | B20: C | C20: GARRAFA | D20: GARRAFAS DON BOSCO | F20: CARGA DE GARRAFA | G20: 6500 | K20: 6500
A21: 45883 | B21: C | C21: EMPLEADA | D21: EMPLEADA | E21: 1 | F21: MILI TRABAJO EL 17/08 | G21: 25000 | K21: 25000
A22: 45887 | B22: C | C22: PLAGAS | D22: LUGONES | E22: 1 | F22: CONTROL DE PLGAS MES JULIO | G22: 16000 | K22: 16000
A23: 45887 | B23: C | C23: CONTADOR | D23: JORGE | E23: 1 | F23: PAGO INICIO ACTIVIDAD JORGE | G23: 10000 | L23: 10000
A24: 45888 | B24: C | C24: BATERIA | D24: JACOB | E24: 1 | F24: COMPRA DE BATERIA | G24: 85000 | K24: 85000
A25: 45888 | B25: C | C25: GARRAPIÑADA | D25: GLORIA | E25: 5 | F25: 5 KG DE GARRAPIÑADA ($7.000 X KG) | G25: =7000*5 -> 35000 | K25: 0
A26: 45893 | B26: C | C26: EMPLEADA | D26: EMPLEADA | E26: 1 | F26: MILI TRABAJO EL 17/08 | G26: 25000 | K26: 25000
A27: 45894 | B27: C | C27: CERRAJERIA | D27: CERRAJERIA | E27: 1 | F27: LLAVE CANDADO | G27: 5000 | K27: 5000
A28: 45894 | B28: C | C28: BOLSAS | D28: PLASTICOS BLANCOS | E28: 400 | F28: BOLSAS PARA GARRAPIÑADAS | G28: 3200 | K28: 3200
A29: 45886 | B29: C | C29: CUBANITO BAÑADOS | D29: MAXI | E29: 200 | F29: 1 CAJA X 200 CUBANITOS BAÑADOS ($333,00 X UNIDAD) | G29: 66600
A30: 45892 | B30: C | C30: CUBANITO BAÑADO | D30: MAXI | E30: 400 | F30: 1 CAJA X 400 CUBANITOS BAÑADOS ($358,00 X UNIDAD) | G30: 143200
A31: 45892 | B31: C | C31: DULCE DE LECHE | D31: MAXI | E31: 2 | F31: 2 POTE X 10KG DULCE DE LECHE PIGUENSE | G31: =25000+25000 -> 50000
A32: 45892 | B32: C | C32: CUBANITO COMUN | D32: MAXI | E32: 400 | F32: 1 CAJA X 400 CUBANITOS COMUNES ($156,00 X UNIDAD) | G32: 62400 | K32: =G29+G30+G31+G32 -> 322200
A33: 45892 | B33: C | C33: DULCE DE LECHE | D33: LUZ AZUL | E33: 2 | F33: 2 POTE X 10KG DULCE DE LECHE LUZ AZUL | G33: =41032+41032 -> 82064
A34: 45898 | B34: C | C34: CUBANITO COMUN | D34: MAXI | E34: 400 | F34: 1 CAJA X 400 CUBANITOS COMUNES ($156,00 X UNIDAD) | G34: 62400 | K34: =G34 -> 62400
A35: 45898 | B35: C | C35: ARRMACO | D35: ARRUMACO | E35: 2 | F35: 2 DELANTALES NEGROS ADELANTO | G35: 12000 | K35: 0 | L35: =G35 -> 12000
A40: 45854 | B40: M | C40: CUBANITO COMUN | D40: MAXI | E40: 400 | F40: 1 CAJA X 400 CUBANITOS COMUNES ($156,00 X UNIDAD) | G40: =156*400 -> 62400
A41: 45854 | B41: M | C41: CUBANITO BAÑADO | D41: MAXI | E41: 300 | F41: 1 CAJA X 300 CUBANITOS BAÑADOS ($333,00 X UNIDAD) | G41: =333*300 -> 99900
A42: 45854 | B42: M | C42: DULCE DE LECHE | D42: MAXI | E42: 1 | F42: 1 POTE X 10KG DULCE DE LECHE LUZ AZUL | G42: 41032 | K42: 0
A43: 45853 | B43: M | C43: GARRAPIÑADA | D43: SEÑORA | E43: 3 | F43: 3 KG DE GARRAPIÑADA ($7.000 X KG) | G43: 21000 | K43: 0
A44: 45855 | B44: C | C44: CONTADOR | D44: JORGE | F44: PAGO INICIO ACTIVIDAD JORGE | G44: 20000 | L44: 0
...

Sheet VENTAS AGOSTO
A1: MES:
B2: CUBANITOS | E2: METODO DE PAGO | G2: TOTAL | I2: MES AGOSTO
A3: DIA | B3: COMUNES | C3: BAÑADOS | D3: OTRO | E3: EFECTIVO | F3: TRANSFERENCIA | G3: VENTAS $
A4: 45870 | B4: =5+12+6+3 -> 26 | C4: =9+1+6+3 -> 19 | D4: =1+1 -> 2 | E4: =10800+6700+11800+12600+6300 -> 48200 | F4: 0 | G4: =E4+F4 -> 48200 | I4: Tranferencia | J4: =SUMIF(F4:F21,">0") -> 677500
A5: 45871 | B5: =6+20+2+4+6+6+2+4+6+3 -> 59 | C5: =3+6+6+6+4+4+3+4+6+4+6+5 -> 57 | D5: 2 | E5: =2000+3600+12600+7200+9000+4800+9000+9000+8400+12600 -> 78200 | F5: =18000+8400+10200+8700 -> 45300 | G5: =E5+F5 -> 123500 | I5: efectivo | J5: =SUMIF(E4:E21,">0") -> 908600
A6: 45872 | B6: =3+2+24+6+6+6+6+12+4+15+3+3+6+6+9+6+3+12 -> 132 | C6: =3+6+6+5+3+6+9+12+12+3 -> 65 | D6: =2+1+1+1 -> 5 | E6: =4400+5400+6400+1000+12600+3600+13500+5400+7200+10800 -> 70300 | F6: =6300+21600+12600+10800+8700+6300+12600+19900+19800+14800 -> 133400 | G6: =E6+F6 -> 203700 | I6: TOTAL | J6: =J4+J5 -> 1586100
A7: 45873 | B7: =6+3+6+1+3+2 -> 21 | C7: =12+3+6+3 -> 24 | D7: 1 | E7: =19800+6900+7300+1800 -> 35800 | F7: =6300+5400 -> 11700 | G7: =E7+F7 -> 47500 | I7: CONSUMO CUBANITOS
A8: 45874 | B8: =6+2+12+4 -> 24 | C8: =4+6+2+4 -> 16 | D8: 1 | E8: =4800+10800+4800+3600 -> 24000 | F8: =12600+5200 -> 17800 | G8: =E8+F8 -> 41800 | I8: COMUNES | J8: BAÑADOS
A9: 45875 | B9: =2+4+2+6+2 -> 16 | C9: =12+4+4+6+6 -> 32 | E9: =14400+1800+8400+6600+12600+1800 -> 45600 | F9: =7200 -> 7200 | G9: =E9+F9 -> 52800 | I9: =SUM(B4:B20) -> 806 | J9: =SUM(C4:C20) -> 641
A10: 45876 | B10: =6+3+3 -> 12 | C10: 3 | D10: =1+2 -> 3 | E10: 0 | F10: =8200+2700+6300+2000 -> 19200 | G10: =E10+F10 -> 19200
A11: 45877 | B11: =15+2+4+4+6+6+1+4+2 -> 44 | C11: =3+8+4+6+6+1+3+4+2 -> 37 | D11: 3 | E11: =13500+9300+8400+12600+7200+2100+3600+4200 -> 60900 | F11: =13200+8400+5400 -> 27000 | G11: =E11+F11 -> 87900
A12: 45878 | B12: =3+3+4+8+6+5+4+1+6+2+3+10+2+6+12 -> 75 | C12: =2+1+3+4+8+6+6+2+5+2+1+6+4+3+4+6+1 -> 64 | D12: =2+2 -> 4 | E12: =4400+3900+6300+8400+7200+9000+6900+9600+3300+1200+6300+9000+6600 -> 82100 | F12: =9600+9200+5400+12600+6600+5400+10800+7200+1200 -> 68000 | G12: =E12+F12 -> 150100
A13: 45879 | B13: =6+2+5+4+4+6+9+6+6+12+2+6+18+6+9+6+6+6+3+6 -> 128 | C13: =3+6+2+4+3+6+3+2+9+6+9+5+6+10+4+6+6+2+3+6+12+6+3+6+18+4 -> 150 | D13: =2+1+1+3+1+2+3 -> 13 | E13: =3600+2000+4200+4500+9400+7200+8200+3600+7800+18900+6000+6600+11700+16000+14600+12600+21600+3000 -> 161500 | F13: =12600+12600+10800+15600+12000+10800+13600+23400+7800+12600+3800+6300+4800 -> 146700 | G13: =E13+F13 -> 308200
A14: 45880 | B14: =8+6+2+3 -> 19 | C14: =1+3 -> 4 | D14: 2 | E14: =9200+5400+3000 -> 17600 | F14: =6300 -> 6300 | G14: =E14+F14 -> 23900
A15: 45881 | B15: =3+3+4 -> 10 | C15: =3+2 -> 5 | D15: 1 | E15: =6300+5400+4600 -> 16300 | G15: =E15+F15 -> 16300
A16: 45882 | B16: =4+1+2 -> 7 | C16: =4+5+2+2+2 -> 15 | D16: 1 | E16: =8400+7200+3300+5200 -> 24100 | F16: =2400 -> 2400 | G16: =E16+F16 -> 26500
A17: 45883 | B17: =3+6+5+3+4+12 -> 33 | C17: =3+6+2 -> 11 | D17: 1 | E17: =6300+4500+5100+11800 -> 27700 | F17: =12600+3600 -> 16200 | G17: =E17+F17 -> 43900
A18: 45884 | B18: =3+24+3+2 -> 32 | C18: =8+4+3+3+3+6+12 -> 39 | D18: =1+1 -> 2 | E18: =9600+7300+3600+2800+14400 -> 37700 | F18: =4800+21600+6300+7200 -> 39900 | G18: =E18+F18 -> 77600
A19: 45885 | B19: =4+4+6+6+6+6+6+8+4 -> 50 | C19: =2+6+6+4+10+1+6 -> 35 | D19: 2 | E19: =6000+5600+12600+5400+4800+5400+5000+1200 -> 46000 | F19: =12600+7000+12600+7200+3600 -> 43000 | G19: =E19+F19 -> 89000
A20: 45886 | B20: =3+6+6+3+6+4+8+12+5+6+6+4+3+8+5+3+6+4+8+2+6+4 -> 118 | C20: =1+6+12+3+6+2+4+4+6+6+1+3+4+2+5 -> 65 | D20: 7 | E20: =3900+6400+7200+6300+12600+6000+10800+12600+7200+5700+5400+4600+12000+5200+5400 -> 111300 | F20: =19800+12000+9300+14600+4600+3700+6300+9600 -> 79900 | G20: =E20+F20 -> 191200
A21: 45887 | B21: =3+3+2 -> 8 | C21: =6+3+7+1 -> 17 | E21: =2700+8400+3000+7200 -> 21300 | F21: =7200+6300 -> 13500 | G21: =E21+F21 -> 34800
A22: 45888 | B22: =3 -> 3 | C22: =8+4+2 -> 14 | D22: =2+1 -> 3 | E22: =9600+2400 -> 12000 | F22: =2000+2700+5800 -> 10500 | G22: =E22+F22 -> 22500
A23: 45889 | B23: =1+3+3+2+6+3+2 -> 20 | C23: =3+8+3+6+4+3+4 -> 31 | D23: 1 | E23: =900+6300+9600+6600+5400+6600 -> 35400 | F23: =6300+8200+6300 -> 20800 | G23: =E23+F23 -> 56200
A24: 45890 | B24: =3+12+6+6+2+12 -> 41 | C24: =6+6+1+6 -> 19 | E24: =2700+10800+12600+12600+1600+1200+10800+7200 -> 59500 | G24: =E24+F24 -> 59500
A25: 45891 | B25: =6+4+2+6+4+12+6+6 -> 46 | C25: =6+10+4+6+2+6+2+12 -> 48 | E25: =16600+8600+6000 -> 31200 | F25: =12600+12600+10800+12600+7800+14400 -> 70800 | G25: =E25+F25 -> 102000
A26: 45892 | B26: =2+6+6+3+6+4+6+1+12+2+6+2+6+3+4+1+2+8+9+2+15 -> 106 | C26: =4+6+6+3+6+4+9+6+2+3+8+4+4+3+2 -> 70 | D26: =2+1+3+1+1+1 -> 9 | E26: =6600+12600+7400+2000+7300+8400+5400+11700+18000+4800+6300+13200+1000+5700+6600+8200+11700+5200+13500 -> 155600 | F26: =5200+12600+4200+5400+5400 -> 32800 | G26: =E26+F26 -> 188400
A27: 45893 | B27: =8+6+9+3+2+4+12+12+6+6+6+1+12+8+4+4+6+5+8 -> 122 | C27: =6+3+6+2+1+8+12+6+5+4+4+12+7 -> 76 | D27: =2+2+2+1+1 -> 8 | E27: =7200+12600+11700+11900+13200+10800+12600+5400+5400+6900+10800+12000+1000+19800+7200 -> 148500 | F27: =4200+3200+25200+10400+3600+13900 -> 60500 | G27: =E27+F27 -> 209000
A28: 45894 | B28: =6+6+4 -> 16 | C28: 4 | E28: 5400 | F28: =5400+8400 -> 13800 | G28: =E28+F28 -> 19200
A29: 45895 | B29: =4+1+1+3+2+2+2+3+6 -> 24 | C29: =2+1+4+3+6+4+1+3+6+6 -> 36 | D29: =1+2 -> 3 | E29: =6000+2100+4800+7200+6600+3000+5400+9200 -> 44300 | F29: =900+6300+7300+7200 -> 21700 | G29: =E29+F29 -> 66000
A30: 45896 | B30: =6+10+1+2 -> 19 | C30: =2+3+6+4 -> 15 | E30: =5400+9000+1800+7200+4800 -> 28200 | F30: =2400+4500 -> 6900 | G30: =E30+F30 -> 35100
A31: 45897 | B31: =9+6+3 -> 18 | C31: =9+6+2+12+2 -> 31 | D31: 2 | E31: =18900+7800+2700+4400 -> 33800 | F31: =7200+14400 -> 21600 | G31: =E31+F31 -> 55400
A32: 45898 | B32: =3+6+3+2+2+6+4 -> 26 | C32: =3+4+4+4+6+2+8 -> 31 | D32: 4 | E32: =2700+10600+6600+13200 -> 33100 | F32: =5400+6300+4800+12600+2400 -> 31500 | G32: =E32+F32 -> 64600
A33: 45899 | B33: =2+6 -> 8 | C33: =2+9+4+6+12+9 -> 42 | D33: =2+2 -> 4 | E33: =2400+6600+7200+21800+10800+2000 -> 50800 | F33: =10800 -> 10800 | G33: =E33+F33 -> 61600
A34: 45900 | B34: =4+1+3+18+6 -> 32 | C34: =2+2+5 -> 9 | E34: =3300+8700+16200+5400 -> 33600 | F34: =6000 -> 6000 | G34: =E34+F34 -> 39600

Sheet GASTOS SEPTIEMBRE
A1: DETALLES GASTOS ENTREGADOS POR CONTRATISTA, FACTURAS "A"
K2: PAGOS
A3: FECHA | B3: ABONO | C3: RUBRO | D3: PROVEEDOR | E3: CANTIDAD | F3: DESCRIPCIÓN | G3: $ c/IVA+Ing.Br | H3: IVA | I3: 1/2IVA | J3: Perc.Ing.Bruto | K3: EFECTIVO | L3: TRANFERENCIA | M3: PEYA WALLET
A4: 45906 | B4: C | C4: DULCE DE LECHE | D4: LUZ AZUL | E4: 1 | F4: 1 POTE X 10KG DULCE DE LECHE LUZ AZUL | G4: 41000 | K4: 41000
A5: 45907 | B5: C | C5: CUBANITO COMUN | D5: MAXI | E5: 400 | F5: 1 CAJA X 400 CUBANITOS COMUNES ($156,00 X UNIDAD) | G5: 62400
A6: 45907 | B6: C | C6: CUBANITO BAÑADO | D6: MAXI | E6: 400 | F6: 1 CAJA X 400 CUBANITOS BAÑADOS ($358,00 X UNIDAD) | G6: 143200
A7: 45907 | B7: C | C7: DULCE DE LECHE | D7: MAXI | E7: 2 | F7: 1 POTE X 10KG DULCE DE LECHE PIGUENSE | G7: 51000 | K7: =SUM(G5:G7) -> 256600
A8: 45910 | B8: C | C8: VESTIMENTA | D8: ARRUMACO | E8: 1 | F8: 2 DELANTALES + 2 COFIA | G8: =12000+10000 -> 22000 | K8: =G8 -> 22000
A9: 45911 | B9: C | C9: IMPUESTO | D9: MUNICIPALIDAD | E9: 1 | F9: TASA SEGURIDAD E HIGIENE SEPTIEMBRE 2025 | G9: 14384 | L9: =G9 -> 14384
A10: 45911 | B10: C | C10: IMPUESTO | D10: ARCA | E10: 1 | F10: MONOTRIBUTO MES SEPTIEMBRE | G10: 11677.6 | L10: =G10 -> 11677.6
A11: 45912 | B11: C | C11: DULCE DE LECHE | D11: JULIA | E11: 2 | F11: 1 POTE X 10KG DULCE DE LECHE PIGUENSE | G11: 51000 | K11: =SUM(G11) -> 51000
A12: 45907 | B12: C | C12: CUBANITO COMUN | D12: MAXI | E12: 400 | F12: 1 CAJA X 400 CUBANITOS COMUNES ($156,00 X UNIDAD) | G12: 62400
A13: 45907 | B13: C | C13: CUBANITO BAÑADO | D13: MAXI | E13: 400 | F13: 1 CAJA X 400 CUBANITOS BAÑADOS ($358,00 X UNIDAD) | G13: 143200
A14: 45907 | B14: C | C14: CUBANITO BAÑADO | D14: MAXI | E14: 400 | F14: 1 CAJA X 400 CUBANITOS BAÑADOS BLANCOS ($358,00 X UNIDAD) | G14: 143200 | K14: =G12+G13+G14 -> 348800
A15: 45913 | B15: C | C15: GARRAPIÑADA | D15: CHICA | E15: 5 | F15: 35KG DE GARRAPIÑADA ($10.000 X KG) | G15: =10000*5 -> 50000 | K15: 0 | L15: =G15 -> 50000
A16: 45915 | B16: C | C16: REPUESTOS | D16: NITRAM | E16: 1 | F16: REPUESTOS PARA HACER PUNTERA DE CUBANERA | G16: 12750 | K16: 0 | L16: =G16 -> 12750
A17: 45916 | B17: C | C17: DULCE DE LECHE | D17: LUZ AZUL | E17: 2 | F17: 2 POTE X 10KG DULCE DE LECHE LUZ AZUL (42261.50) | G17: 84523 | K17: =G17 -> 84523
A18: 45916 | B18: C | C18: DULCE DE LECHE | D18: LUZ AZUL | E18: 4 | F18: 4 POTE X 10KG DULCE DE LECHE LUZ AZUL (42261.50) | G18: 169046 | L18: =G18 -> 169046
A19: 45916 | B19: C | C19: DULCE DE LECHE | D19: JULIA | E19: 6 | F19: 6 POTE X 10KG DULCE DE LECHE PIGUENSE ($25.000) | G19: =25000*6 -> 150000 | K19: =SUM(G19) -> 150000
A20: 45916 | B20: C | C20: REPUESTOS | D20: ALFA RODAMIENTO | E20: 1 | F20: REPUESTOS ORRIN PARA CUBANERA | G20: 1500 | K20: =G20 -> 1500
A21: 45917 | B21: C | C21: BOLSAS | D21: PAPELERA SAN LUIS | E21: 600 | F21: 500 BOLSAS N3L+ 100 BOLSAS N4 | G21: 13800 | L21: 13800
A22: 45918 | B22: C | C22: CONTADOR | D22: JORGE | E22: 1 | F22: PAGO MENSUAL JORGE | G22: 10000 | L22: =G22 -> 10000
A23: 45918 | B23: C | C23: GARRAPIÑADA | D23: GLORIA | E23: 10 | F23: 10 KG DE GARRAPIÑADA ($8.000 X KG) | G23: =8000*10 -> 80000 | K23: =G23 -> 80000
A24: 45919 | B24: C | C24: CUBANITO COMUN | D24: MAXI | E24: 600 | F24: 1 CAJA X 400 CUBANITOS COMUNES ($156,00 X UNIDAD) | G24: =62400+31200 -> 93600
A25: 45919 | B25: C | C25: CUBANITO BAÑADO | D25: MAXI | E25: 400 | F25: 1 CAJA X 400 CUBANITOS BAÑADOS ($358,00 X UNIDAD) | G25: 143200 | L25: =G24+G25 -> 236800
A26: 45918 | B26: C | C26: DULCE DE LECHE | D26: LUZ AZUL | E26: 3 | F26: 3 POTE X 10KG DULCE DE LECHE LUZ AZUL (42261.50) | G26: =42261.5*3 -> 126784.5 | K26: =G26 -> 126784.5 | L26: 0
A27: 45919 | B27: C | C27: PEDIDO YA | D27: PEDIDO YA | E27: 1 | F27: GASTOS DE COMICION 1-9 AL 7-9 | G27: =8925.94+415.87+2079.59 -> 11421.4 | K27: 0 | M27: =G27 -> 11421.4
A28: 45922 | B28: C | C28: PLAGAS | D28: LUGONES | F28: CONTROL DE PLGAS MES septiembre | G28: 16000 | L28: =G28 -> 16000
A29: 45922 | B29: C | C29: GARRAFA | D29: GARRAFAS DON BOSCO | F29: CARGA DE GARRAFA | G29: 7000 | K29: 7000
A30: 45924 | B30: C | C30: DULCE DE LECHE | D30: JULIA | E30: 4 | F30: 4 POTE X 10KG DULCE DE LECHE PIGUENSE ($25.000) | G30: =25000*4 -> 100000 | K30: =SUM(G30) -> 100000
A31: 45926 | B31: C | C31: CUBANITO COMUN | D31: MAXI | E31: 1200 | F31: 3 CAJA X 400 CUBANITOS COMUNES ($156,00 X UNIDAD) | G31: =62400*3 -> 187200
A32: 45926 | B32: C | C32: CUBANITO BAÑADO | D32: MAXI | E32: 2000 | F32: 5 CAJA X 400 CUBANITOS BAÑADOS ($358,00 X UNIDAD) | G32: =143200*5 -> 716000 | K32: =G31+G32-25000-62400 -> 815800
A33: 45929 | B33: C | C33: EMPLEADA | D33: EMPLEADA | E33: 2 | F33: MILI TRABAJO EL 27/09+28/09 | G33: =30000*2 -> 60000 | K33: =G33 -> 60000
A34: 45930 | B34: C | C34: PEDIDO YA | D34: PEDIDO YA | E34: 1 | F34: GASTOS DE COMICION 9-9 AL 14-9 | G34: =27287.49+4544.8+9231.36 -> 41063.65 | K34: 0 | M34: =G34 -> 41063.65
A35: 45930 | B35: C | C35: EXTRACCION | D35: ERICA | F35: EXTRACCION MES SEPTIEMBRE EFECTIVO | G35: 1300000 | K35: 800000 | L35: 500000
A36: 45930 | B36: C | C36: EXTRACCION | D36: MATIAS | F36: EXTRACCION MES SEPTIEMBRE BANCARIZADA X TRANFERENCIAS | G36: 1300000 | K36: 400000 | L36: 900000
B37: C
B38: C
B39: C
B40: C
...

Sheet VENTAS SEPTIEMBRE
A1: MES:
B2: CUBANITOS | E2: METODO DE PAGO | H2: TOTAL | J2: MES SEPTIEMBRE
A3: DIA | B3: COMUNES | C3: BAÑADOS | D3: OTRO | E3: EFECTIVO | F3: TRANSFERENCIA | G3: PEDIDOS YA | H3: VENTAS $
A4: 45901 | B4: =2+4+6+2 -> 14 | C4: =4+2+2 -> 8 | E4: =1800+4200 -> 6000 | F4: =8400+7800 -> 16200 | H4: =E4+F4 -> 22200 | J4: Tranferencia | K4: =SUMIF(F4:F31,">0") -> 1878100
A5: 45902 | B5: =2+12+6 -> 20 | C5: =6+6 -> 12 | E5: =2700+10800+7200 -> 20700 | F5: =12600 -> 12600 | H5: =E5+F5 -> 33300 | J5: efectivo | K5: =SUMIF(E4:E31,">0") -> 3134830
A6: 45903 | B6: =6+6+4+6+2+4+6 -> 34 | C6: =2+3+4+4 -> 13 | D6: 4 | E6: =5400+5400+3600+2000+6800 -> 23200 | F6: =7800+5400+8400+5400 -> 27000 | H6: =E6+F6 -> 50200 | J6: PedidosYA | K6: =SUMIF(G4:G34,">0") -> 364950
A7: 45904 | B7: =2+2+5 -> 9 | C7: =4+4+2+5+8 -> 23 | D7: 1 | E7: =6600+4800+5200+10500+9600 -> 36700 | H7: =E7+F7 -> 36700 | J7: TOTAL | K7: =K4+K5+K6 -> 5377880
A8: 45905 | B8: =10+6+4+6+6+8+6+6+2+1+12 -> 67 | C8: =12+2+3+8+2+6+2+10+6+5+9+2 -> 67 | D8: 3 | E8: =11400+3600+5400+15200+12600+5400+5400+1000+10800+4200 -> 75000 | F8: =14400+7800+9600+12000+900+18000 -> 62700 | G8: =10030+6800 -> 16830 | H8: =E8+F8 -> 137700
A9: 45906 | B9: =6+2+12+4+1+1+6+6+10+4+12+2+1 -> 67 | C9: =6+6+4+4+3+6+4+4+6+4+12+2+1 -> 62 | D9: =2+2 -> 4 | E9: =6600+8400+4500+5400+4800+14600+9000+8400+10800+2100 -> 74600 | F9: =7200+10800+7200+5700+14400+4200 -> 49500 | G9: =16740 -> 16740 | H9: =E9+F9 -> 124100 | J9: CONSUMO CUBANITOS
A10: 45907 | B10: =3+4+3+8+4+3+18+3+6+3+6+12+3+4+12+12+6+6+6+4 -> 126 | C10: =3+5+3+2+6+6+6+6+8+6+6+6+6+12+12+6+5+4+4+6+4+6+8+6 -> 142 | D10: =3+1 -> 4 | E10: =7200+16200+7200+12600+12300+14580+10800+9900+7200+3000+14400+3600+5940+7200+5200+4800+4800+1000+4800+13200 -> 165920 | F10: =6300+6300+6000+9900+9900+7200+10800+25200+6000+12600+7200 -> 107400 | G10: =11160+8640 -> 19800 | H10: =E10+F10+G10 -> 293120 | J10: COMUNES | K10: BAÑADOS
A11: 45908 | B11: =8+6+12+1+1+2 -> 30 | C11: =6+12+3+1+6+2 -> 30 | E11: =7200+7200+10000+3600+8000+4200 -> 40200 | F11: =19800+800+2100 -> 22700 | H11: =E11+F11+G11 -> 62900 | J11: =SUM(B4:B33) -> 2438 | K11: =SUM(C4:C33) -> 2579
A12: 45909 | B12: =12+2+6+2+2 -> 24 | C12: =6+6+3+2 -> 17 | D12: 1 | E12: =1000+7200+5400+5400+4200+1800 -> 25000 | F12: 7200 | G12: 11880 | H12: =E12+F12+G12 -> 44080
A13: 45910 | B13: =6+6+4+6+4+9+4+3+12 -> 54 | C13: =2+2+4+4+3 -> 15 | E13: =2400+5400+8100+3600+7300 -> 26800 | F13: =7800+8400+3600+10800 -> 30600 | G13: =11700 -> 11700 | H13: =E13+F13+G13 -> 69100
A14: 45911 | B14: =6+4+12+4+4+6+4+4+1+6 -> 51 | C14: =6+12+4+2+2+1+6 -> 33 | D14: 1 | E14: =1000+10800+8400+3600+2400+3600+2100+7200 -> 39100 | F14: =5400+5400+6000+5400 -> 22200 | G14: =29160 -> 29160 | H14: =E14+F14+G14 -> 90460
A15: 45912 | B15: =4+10+6+4+5+3+2 -> 34 | C15: =6+4+5+3+6+1 -> 25 | D15: =2+4 -> 6 | E15: =14600+8400+6300+11200 -> 40500 | F15: =3600+9000+10500+3000 -> 26100 | H15: =E15+F15+G15 -> 66600
A16: 45913 | B16: =12+3+6+2+12+1+4+6+3+6+6+1+8+3 -> 73 | C16: =3+4+6+1+8+6+4+5+3+12+6+3+12+8+3 -> 84 | D16: =1+2 -> 3 | E16: =10800+6400+6600+2000+12500+4800+6000+6300+19800+5400+4500+7200+6300 -> 98600 | F16: =18000+2100+13200+14400+9600 -> 57300 | G16: =7290+8640 -> 15930 | H16: =E16+F16+G16 -> 171830
A17: 45914 | B17: =6+4+6+2+4+6+2+6+3+4+3+8+6+4+8+4+6+6+24+12+6+2+2+18+6+6+6+3+6+4+12+4 -> 199 | C17: =4+4+7+3+2+12+4+2+5+12+12+8+12+4+8+6+6+6+6+4+2+4+12+3+6+12+4 -> 170 | D17: 5 | E17: =5400+5400+10200+4400+6000+14400+17100+3600+12000+13200+7200+12600+23760+7200+7400+4200+5400+5400+14580+3600+23220+2620 -> 208880 | F17: =8400+4800+7200+6600+7800+13200+2700+8200+10800+6600+4800+16200+19800+6300 -> 123400 | G17: =23220+23220+14580+10800 -> 71820 | H17: =E17+F17+G17 -> 404100
A18: 45915 | B18: =12+5+2 -> 19 | C18: =2+4+1 -> 7 | D18: 1 | E18: =10800+4500+8820+1200 -> 25320 | F18: =2400 -> 2400 | H18: =E18+F18+G18 -> 27720
A19: 45916 | B19: =1+6+12+2+6 -> 27 | C19: =2+12+2+4+1 -> 21 | D19: 2 | E19: =2000+3300+2400+5400+10800+3900 -> 27800 | F19: =14400+6600 -> 21000 | H19: =E19+F19+G19 -> 48800
A20: 45917 | B20: =6+4+6+5 -> 21 | C20: =6+4+8+6+5 -> 29 | E20: =12600+4800+13200 -> 30600 | F20: 10500 | G20: 14580 | H20: =E20+F20+G20 -> 55680
A21: 45918 | B21: =3+4+2+6 -> 15 | C21: =6+2+2 -> 10 | E21: =7200+3600+4200+5400 -> 20400 | F21: =5100 -> 5100 | H21: =E21+F21+G21 -> 25500
A22: 45919 | B22: =3+3+4+12+5+2+3+12 -> 44 | C22: =6+2+1+4+10+5 -> 28 | D22: 2 | E22: =2700+9900+6000+10800+5700+8600+12000+8700 -> 64400 | F22: =0 -> 0 | G22: =11880 -> 11880 | H22: =E22+F22+G22 -> 76280
A23: 45920 | B23: =9+12+8+12 -> 41 | C23: =9+6+4+6+18 -> 43 | D23: 1 | E23: =11000+8200+12000+7200 -> 38400 | F23: =10800 -> 10800 | G23: =21870+25920 -> 47790 | H23: =E23+F23+G23 -> 96990
A24: 45921 | B24: =4+10+6+2+4+6+1+9+7+12+1+6+6+8 -> 82 | C24: =8+8+4+2+6+6+3+6+6+7+5+6+6+3+6+6 -> 88 | E24: =2400+12500+4500+15300+6900+11000+12600+3600+7200+7200 -> 83200 | F24: =18600+7200+6900+7200 -> 39900 | G24: =15480+5940+7740+12600+8640+8640+14580 -> 73620 | H24: =E24+F24+G24 -> 196720
A25: 45922 | B25: 3 | C25: 6 | E25: 2700 | G25: 8640 | H25: =E25+F25+G25 -> 11340
A26: 45923 | B26: =3+2+6+2+6+3 -> 22 | C26: =3+6+2+2+6+3 -> 22 | D26: =2+1+1+2 -> 6 | E26: =9000+3400+14600+6300 -> 33300 | F26: =6300+7400+5200 -> 18900 | H26: =E26+F26+G26 -> 52200
A27: 45924 | B27: =12+12+6+4+3 -> 37 | C27: =4+2+3+4+3 -> 16 | E27: =10800+4800+10800+7800+3600 -> 37800 | F27: =3600+4800+6300 -> 14700 | H27: =E27+F27+G27 -> 52500
A28: 45925 | B28: =4+6+2+3+12+6+3+4+3+4+2 -> 49 | C28: =6+1+2+4+3+6+1+6+12+4+6+4 -> 55 | E28: =1200+6000+5400+6300+10800+12600+3900+14400+8400+7200+2700+6600+3000 -> 88500 | F28: =7200+6600+7200+3600 -> 24600 | H28: =E28+F28+G28 -> 113100
A29: 45926 | H29: =E29+F29+G29 -> 0
A30: 45927 | B30: =2+4+12+1+3+6+3+3+4+1+5+2+6+8+12+5+3+3+4+1+6+6+6+2+3+2+6+2+2+3+2+6+6+2+4+9+5+4+3+2+2+4+3+4+8+6+5+8+6+2+1+5+12+2+3+6+2+6+2+2+2+1+6+24+2+3+2+2+2+2+3+12+3+3+2+6+3+8+12+6+12+2+12+4+2+2+3+2+2+1+1+4+2+4+6+3+1+3+4+3+6+3+4+3+6+6+1+4+6+3+3+3+6+7+3+2+3+2+4+3+2+8+4+10+6+2+2+2 -> 549 | C30: =3+6+2+3+4+3+1+8+2+5+1+2+4+5+6+8+2+2+3+2+6+6+4+3+2+6+1+1+3+4+3+3+6+6+8+9+4+4+3+4+3+3+4+1+16+2+4+4+2+12+2+3+3+6+4+2+2+4+4+4+2+1+4+2+3+6+2+2+3+3+6+4+4+3+12+2+4+6+2+2+4+4+2+2+2+4+2+4+6+6+1+4+6+2+6+6+6+2+6+3+3+2+3+1+8+3+1+4+12+4+4+6+6+3+1+8+3+5+3+3+5+3+3+2+2+6+2+6+4+12+5+3 -> 530 | D30: =1+1+3+1+1+1+1+1+2+1 -> 13 | E30: =1800+3600+1800+1200+7200+3300+6300+7200+7500+6300+1200+3300+1200+4200+6000+12600+7200+9600+2400+14400+3600+6600+6600+4200+12600+3000+3000+6300+6600+3600+5400+3600+1800+7200+16200+4400+3600+6300+7200+5700+26400+2400+3000+6600+6900+14400+10800+6400+6600+4800+4800+5400+21600+4200+6300+1800+9000+6300+9900+10200+6300+15600+9000+2400+8400+4200+1200+6600+4200+5200+2100+3600+8400+7200+3600+7200+5400+6300+1200+6200+6000+8400+6300+1200+4800+19800+5700+8400+7200+12600+7500+6300+6300+6000+6300+4200+6000+9900+7200+14400+3600+5400+6000+1800+12000 -> 691200 | F30: =5700+13200+10500+4800+4500+6300+900+5400+12600+12600+6300+12600+18900+9300+8400+6300+6600+8400+5400+2400+5700+2400+6300+12600+5300+2200+4200+6600+4200+2100+4800+4200+4200+6300+10800+6600+7200+25200+7800+2400+10800+4800+4200+5400+7200+7200+4800+7200+4200+7200+2400+6300+3900+14400+3900+9600+11400+6300+5400+3600+7200+4800+9000+900+5400+4200 -> 453900 | H30: =E30+F30+G30 -> 1145100
A31: 45928 | B31: =3+1+3+2+6+6+6+6+3+6+3+6+1+4+6+4+3+2+10+2+6+1+12+3+4+3+10+6+3+12+24+2+1+2+6+6+2+1+6+2+6+6+3+2+6+12+6+2+6+4+4+3+2+6+12+4+6+6+3+3+2+3+6+9+6+5+4+4+1+1+2+6+7+6+1+2+8+4+4+2+4+6+6+6+6+4+12+6+6+2+6+12+6+1+6+1+2+1+12+12+3+3+2+4+4+6+3+4+6+2+6+4+6+3+4+4+6+12+2+2+6+3+3+4+6+4+2+4+2+6+3+12+4+6+6+6+3+3+4+1+6+5+3+2+6+3+3+5+4+6 -> 714 | C31: =2+1+4+8+12+4+2+5+8+6+1+2+1+2+2+6+1+5+2+8+9+2+12+6+6+4+8+6+6+4+6+6+4+6+4+6+1+6+3+5+3+4+4+4+6+3+2+12+5+2+6+6+6+3+7+4+1+6+2+6+3+2+6+6+3+6+3+10+2+6+6+4+1+2+5+2+4+2+12+6+6+8+6+6+2+6+3+6+6+16+4+4+1+2+1+3+2+6+6+6+1+6+2+2+18+8+3+4+2+9+4+4+10+6+6+12+3+8+6+10+6+2+6+4+9+2+6+8+4+2+6+10+12+12+12+36+3+5+2+3+12+6+1+4+2+2+5+6+10+14+3+6+6+3+6+6+2+7+6+6+12+12+9+9+9+6+2+12+12+6+3+9+4+12+12 -> 991 | D31: =3+3+1+3+1 -> 11 | E31: =1200+2400+2000+1800+5400+5400+2400+15600+12600+2700+7200+2700+1200+9000+3300+28000+13200+6300+4800+4800+4800+900+7200+6300+10800+9600+12600+13800+7200+2400+12600+8400+3600+13500+4200+12600+10800+6000+12000+14400+14300+14400+12600+6300+4200+12600+8700+8400+3300+9600+2700+18000+5000+7200+5500+8400+12600+16200+1700+7200+2000+19800+5400+14400+7200+3600+13500+6600+8400+5400+7200+7200+4200+6000+6300+11100+8400+2100+7800+6000+4200+7200+12600+6300+7200+16500+12600+4800+2000+4200+10800+2700+1800+8400+5400+2700+4500+1800+12600+7200+6000+6300+3600+3600+7200+12000+21000+6600+5400+3300+4200+5400+6900+4200+7200+13200+6000+14400+7200+7200+12600+12600+5400+4800+3600+7200+4800+5400+12600+3600+2400+1200+4800+9600+4800+2400+6000+9600+7200+10800+5400+1200+2400+2100+33710+10200 -> 1110010 | F31: =2700+4800+6300+5400+5300+6000+4200+19800+13800+12600+25200+7200+21000+16800+5400+6300+21600+5400+2600+4200+12600+14400+10800+10000+16200+19800+14400+7200+4800+12600+8700+6300+19800+8000+6000+8700+6300+8400+6600+19800+8700+10800+12600+12600+13800+7200+5700+6300+6300+6000+12600+6900+10800+5400+6600+14400+7200+7200+13200+15600+12600+14400+12600+7500+10800+6600+5400+7200+10800+3000+12600 -> 711400 | H31: =E31+F31+G31 -> 1821410
A32: 45929 | H32: =E32+F32+G32 -> 0
A33: 45930 | B33: =3+6+1+3 -> 13 | C33: =4+4+6+2+6+5+3+2 -> 32 | E33: =4800+7200+5000+6300+2400 -> 25700 | F33: =4800+6900 -> 11700 | G33: =14580 -> 14580 | H33: =E33+F33+G33 -> 51980
H34: =E34+F34+G34 -> 0

Sheet GASTOS OCTUBRE
A1: DETALLES GASTOS ENTREGADOS POR CONTRATISTA, FACTURAS "A"
K2: PAGOS
A3: FECHA | B3: ABONO | C3: RUBRO | D3: PROVEEDOR | E3: CANTIDAD | F3: DESCRIPCIÓN | G3: $ c/IVA+Ing.Br | H3: IVA | I3: 1/2IVA | J3: Perc.Ing.Bruto | K3: EFECTIVO | L3: TRANFERENCIA | M3: PEYA WALLET
A4: 45930 | B4: C | C4: PEDIDO YA | D4: PEDIDO YA | E4: 1 | F4: GASTOS DE COMICION 15-9 AL 21-9 | G4: =20677+4894.54+7415.75 -> 32987.29 | K4: 0 | M4: =G4 -> 32987.29
A5: 45940 | B5: C | C5: CUBANITO COMUN | D5: MAXI | E5: 600 | F5: 1 CAJA X 600 CUBANITOS COMUNES ($156,00 X UNIDAD) | G5: =62400+31200 -> 93600 | K5: =G5 -> 93600
A6: 45943 | B6: C | C6: DULCE DE LECHE | D6: JULIA | E6: 4 | F6: 4 POTE X 10KG DULCE DE LECHE PIGUENSE | G6: =25000*4 -> 100000 | K6: =SUM(G6) -> 100000
A7: 45943 | B7: C | C7: CONTADOR | D7: JORGE | E7: 1 | F7: PAGO MENSUAL JORGE | G7: 10000 | L7: =G7 -> 10000
A8: 45941 | B8: C | C8: IMPUESTO | D8: ARCA | E8: 1 | F8: MONOTRIBUTO MES OCTUBRE | G8: 11677.6 | L8: =G8 -> 11677.6
A9: 45930 | B9: C | C9: PEDIDO YA | D9: PEDIDO YA | E9: 1 | F9: GASTOS DE COMICION 22-9 AL 28-9 | G9: =1119.23+235.04 -> 1354.27 | K9: 0 | M9: =G9 -> 1354.27
A10: 45945 | B10: C | C10: EXTRACCION | D10: ERICA | F10: EXTRACCION MES SEPTIEMBRE EFECTIVO | G10: 650000 | K10: 400000 | L10: 250000
A11: 45945 | B11: C | C11: EXTRACCION | D11: MATIAS | F11: EXTRACCION MES SEPTIEMBRE BANCARIZADA X TRANFERENCIAS | G11: 650000 | K11: 350000 | L11: 300000
A12: 45947 | B12: C | C12: PEDIDO YA | D12: PEDIDO YA | E12: 1 | F12: GASTOS DE COMICION 29-9 AL 5-10 | G12: =31291.02+4829.1+7585.22+6600 -> 50305.34 | K12: 0 | M12: =G12 -> 50305.34
A13: 45951 | B13: C | C13: PLAGAS | D13: LUGONES | F13: CONTROL DE PLGAS MES OCTUBRE | G13: 16000 | L13: =G13 -> 16000
A14: 45954 | B14: C | C14: PEDIDO YA | D14: PEDIDO YA | E14: 1 | F14: GASTOS DE COMICION 6-10 AL 12-10 | G14: =54138.37+33500+17314.66+26000-5187.61 -> 125765.42 | K14: 0 | M14: =G14 -> 125765.42
A15: 45958 | B15: C | C15: CUBANITO COMUN | D15: MAXI | E15: 400 | F15: 1 CAJA X 400 CUBANITOS COMUNES ($156,00 X UNIDAD) | G15: 62400
A16: 45958 | B16: C | C16: CUBANITO BAÑADO | D16: MAXI | E16: 400 | F16: 1 CAJA X 400 CUBANITOS BAÑADOS ($358,00 X UNIDAD) | G16: 143200
A17: 45958 | B17: C | C17: CUBANITO BAÑADO | D17: MAXI | E17: 200 | F17: 1 CAJA X 400 CUBANITOS BAÑADOS ($358,00 X UNIDAD) | G17: 71100 | K17: =G15+G16+G17 -> 276700
M19: =203823-G14+5187.61 -> 83245.19
B50: C
B51: C
B52: C
B53: C
B54: C
B55: C
B56: C
B57: C
B58: C
B59: C
B60: C
B61: C
... B80: C
A85: 45854 | B85: M | C85: CUBANITO COMUN
A86: 45906 | B86: C | C86: DULCE DE LECHE | D86: LUZ AZUL | E86: 1 | F86: 1 POTE X 10KG DULCE DE LECHE LUZ AZUL | G86: 41000 | K86: 41000
A87: 45907 | B87: C | C87: CUBANITO COMUN | D87: MAXI | E87: 400 | F87: 1 CAJA X 400 CUBANITOS COMUNES ($156,00 X UNIDAD) | G87: 62400
A88: 45907 | B88: C | C88: CUBANITO BAÑADO | D88: MAXI | E88: 400 | F88: 1 CAJA X 400 CUBANITOS BAÑADOS ($358,00 X UNIDAD) | G88: 143200
A89: 45907 | B89: C | C89: DULCE DE LECHE | D89: MAXI | E89: 2 | F89: 1 POTE X 10KG DULCE DE LECHE PIGUENSE | G89: 51000 | K89: =SUM(G87:G89) -> 256600
A90: 45910 | B90: C | C90: VESTIMENTA | D90: ARRUMACO | E90: 1 | F90: 2 DELANTALES + 2 COFIA | G90: =12000+10000 -> 22000 | K90: =G90 -> 22000
A91: 45911 | B91: C | C91: IMPUESTO | D91: MUNICIPALIDAD | E91: 1 | F91: TASA SEGURIDAD E HIGIENE SEPTIEMBRE 2025 | G91: 14384 | L91: =G91 -> 14384
A92: 45911 | B92: C | C92: IMPUESTO | D92: ARCA | E92: 1 | F92: MONOTRIBUTO MES SEPTIEMBRE | G92: 11677.6 | L92: =G92 -> 11677.6
A93: 45912 | B93: C | C93: DULCE DE LECHE | D93: JULIA | E93: 2 | F93: 1 POTE X 10KG DULCE DE LECHE PIGUENSE | G93: 51000 | K93: =SUM(G93) -> 51000
...

Sheet VENTAS OCTUBRE
A1: MES:
B2: CUBANITOS | E2: METODO DE PAGO | H2: TOTAL | J2: MES OCTUBRE
A3: DIA | B3: COMUNES | C3: BAÑADOS | D3: OTRO | E3: EFECTIVO | F3: TRANSFERENCIA | G3: PEDIDOS YA | H3: VENTAS $
A4: 45931 | B4: =6+6+6+5+2+4+2 -> 31 | C4: =6+6+6+6+2 -> 26 | D4: =3+1+2 -> 6 | E4: =15000+7200+7200+6600+2400+5400+1800 -> 45600 | F4: =4500+9000+6000 -> 19500 | H4: =E4+F4 -> 65100 | J4: Tranferencia | K4: =SUMIF(F4:F31,">0") -> 738000
A5: 45932 | B5: =6+6+4+6+3 -> 25 | C5: =4+12+3 -> 19 | E5: =5400 -> 5400 | F5: =5400+8400+14400 -> 28200 | G5: =6600+8100 -> 14700 | H5: =E5+F5 -> 33600 | J5: efectivo | K5: =SUMIF(E4:E31,">0") -> 1388600
A6: 45933 | B6: 1 | C6: =4+6 -> 10 | E6: =5700+7200 -> 12900 | H6: =E6+F6 -> 12900 | J6: PedidosYA | K6: =SUMIF(G4:G34,">0") -> 580660
A7: 45934 | B7: =2+6+2+6+4+2+6+12+4 -> 44 | C7: =6+6+9+6+4+2+8+2+12+4 -> 59 | D7: 1 | E7: =7200+12600+4200+10800 -> 34800 | F7: =12600+6600+7800+13200+14400+8400 -> 63000 | G7: =9600+7800 -> 17400 | H7: =E7+F7 -> 97800 | J7: TOTAL | K7: =K4+K5+K6 -> 2707260
A8: 45935 | B8: =2+12+8+12+6+12+6+24+18+2+8+4+6+6+6+12+6+2+6+6+8+9+6+6+4+2 -> 199 | C8: =2+2+6+6+6+6+7+3+8+4+4+6+4+6+6+4+6+6+2+4+9+6+6+4 -> 123 | D8: =1+3+1+1 -> 6 | E8: =6600+16200+12600+21600+3600+25800+8400+9600+12600+4200+5400+10800+6600+4800 -> 148800 | F8: =7200+10800+10800+12600+12000+12600+12600+4800+12000+18900+5400+7200+5400 -> 132300 | G8: =9600+9600+11200+8600+6600+22800+6600 -> 75000 | H8: =E8+F8 -> 281100
A9: 45936 | B9: =12+2+3 -> 17 | C9: =5+3+6+9 -> 23 | D9: 3 | E9: =10800+3600+3000+7200+13500 -> 38100 | F9: =7800 -> 7800 | H9: =E9+F9 -> 45900 | J9: CONSUMO CUBANITOS
A10: 45937 | B10: =6+3+13+3+6+6+4+18 -> 59 | C10: =6+6+1+3+5+6+4+6+12 -> 49 | D10: =3+3 -> 6 | E10: =16200+6900+9900+12600+4800+5000+16200+14000 -> 85600 | F10: =7200+3600+7200 -> 18000 | G10: =12500 -> 12500 | H10: =E10+F10 -> 103600 | J10: COMUNES | K10: BAÑADOS
A11: 45938 | B11: =6+2+1+8+4 -> 21 | C11: =2+4+4 -> 10 | E11: =5400+1500+2400+900+8400 -> 18600 | G11: =15200 -> 15200 | H11: =E11+F11 -> 18600 | J11: =SUM(B4:B33) -> 1244 | K11: =SUM(C4:C33) -> 1103
A12: 45939 | B12: =8+2+1+1+8+4+6+2 -> 32 | C12: =2+6+12+3+6+6+5+2 -> 42 | D12: 3 | E12: =7200+1800+17400+4000+900+7200+7200+5400+4200 -> 55300 | F12: =2400+7200+9600 -> 19200 | G12: =9600 -> 9600 | H12: =E12+F12 -> 74500
A13: 45940 | B13: =6+4+12+12+3+12+10+12+6 -> 77 | C13: =4+9 -> 13 | D13: =1+3+1 -> 5 | E13: =4800+10800+13800+10200+5400 -> 45000 | F13: =6600+3600+10800 -> 21000 | G13: =17700+13200 -> 30900 | H13: =E13+F13 -> 66000
A14: 45941 | B14: =6+6+6+6+6+3+5 -> 38 | C14: =12+6+4+6+6+2+10+12+9+6+1 -> 74 | D14: =3+1 -> 4 | E14: =8500+4800+7200+2400+12000+19800 -> 54700 | F14: =14400+5400+5700 -> 25500 | G14: =9600+17400+6600+17700+9600 -> 60900 | H14: =E14+F14 -> 80200
A15: 45942 | B15: =6+1+6+1+4+12+3+6+6+6+2+6+3+3+6+4+1+10+1+2+4+4+4+7+6 -> 114 | C15: =2+6+7+4+6+12+3+3+6+2+2+6+3+3+5+5+2+6+4+12+7+4+8+8+8+13+6 -> 153 | D15: =1+2+3+3 -> 9 | E15: =5400+3300+7200+6300+6000+12600+9800+9000+6000+3600+6900+11400+900+6600+16200+13200+13200+21900+7200 -> 166700 | F15: =9300+9600+5400+5400+4200+9900+6300+7200+14400+8400+8400 -> 88500 | G15: =16200+13200+19200+6400 -> 55000 | H15: =E15+F15 -> 255200
A16: 45943 | B16: =6+2+8+4+12+4+1+1+4+6+6+4+3+3 -> 64 | C16: =4+1+2+3+4+1 -> 15 | D16: 1 | E16: =1800+7200+3600+3600+2100+4500+3600+3600+5400+5400+2700 -> 43500 | F16: =5400+4800+10800+8400+3900 -> 33300 | H16: =E16+F16 -> 76800
A17: 45944 | B17: =3+4+8+8+6 -> 29 | C17: =3+4+2 -> 9 | D17: 1 | E17: =6300+3700+8400+12000+2400 -> 32800 | F17: =5400 -> 5400 | H17: =E17+F17 -> 38200
A18: 45945 | B18: =8+6+4 -> 18 | C18: =4+6+6+6 -> 22 | E18: =4800+7200 -> 12000 | F18: =7200+10800 -> 18000 | G18: =16200 -> 16200 | H18: =E18+F18 -> 30000
A19: 45946 | B19: =12+2+12+4+12+1+2 -> 45 | C19: =6+1+1+2+3+3 -> 16 | D19: =3+3 -> 6 | E19: =18200+3000+1200+10800+6600+3300+1800+3600 -> 48500 | F19: =10800+7800 -> 18600 | H19: =E19+F19 -> 67100
A20: 45947 | B20: =10+4+4 -> 18 | C20: =10+6+4+6 -> 26 | E20: =12000+9000+7200+8400+3600 -> 40200 | F20: =7200 -> 7200 | H20: =E20+F20 -> 47400
A21: 45948 | B21: =4+6+2 -> 12 | C21: =6+3+4+9+6+3+4+24+4+6 -> 69 | D21: =3 -> 3 | E21: =9600+3600+3600+14400+3000+6600+28800+4800 -> 74400 | F21: =4800+3600+7200 -> 15600 | G21: =16200 -> 16200 | H21: =E21+F21 -> 90000
A22: 45949 | B22: =3+2+2+6+12+2 -> 27 | C22: =4+4+10+2+4+6+5 -> 35 | D22: =3+3 -> 6 | E22: =6600+12000+4200+8400+4800+10000 -> 46000 | G22: =9700+13200+10200 -> 33100 | H22: =E22+F22 -> 46000
A23: 45950 | B23: =8+2+4+2 -> 16 | C23: =4+4 -> 8 | E23: =7200+6600 -> 13800 | F23: =6600+3600 -> 10200 | H23: =E23+F23 -> 24000
A24: 45951 | B24: =8 -> 8 | C24: =4+7 -> 11 | D24: =3 -> 3 | E24: =4800+7200 -> 12000 | F24: =8400+3000 -> 11400 | H24: =E24+F24 -> 23400
A25: 45952 | B25: =4+4+6+2+6+3+6 -> 31 | C25: =4+1+4+4 -> 13 | D25: =3 -> 3 | E25: =8400+4800+5400+5400 -> 24000 | F25: =5400+6600+10500 -> 22500 | H25: =E25+F25 -> 46500
A26: 45953 | B26: =4 -> 4 | C26: =4+6+4+8 -> 22 | E26: =8400+7200+4800+9600 -> 30000 | H26: =E26+F26 -> 30000
A27: 45954 | B27: =9+1 -> 10 | C27: =3+6+2+2 -> 13 | D27: 3 | E27: =3600+11000+2400+3300 -> 20300 | F27: 7200 | H27: =E27+F27 -> 27500
A28: 45955 | B28: =6+6+10+12+4+8+4+9+5 -> 64 | C28: =3+6+6+8+4+8+1 -> 36 | D28: =6+3 -> 9 | E28: =6000+3600+16800+10500+4800+19200 -> 60900 | F28: =15600+10800+9600+4800+4800+9600 -> 55200 | G28: =5700+13000+28800 -> 47500 | H28: =E28+F28 -> 116100
A29: 45956 | B29: =6+10+14+6+6+6+6+8+6+6+2+2+12+9+8+3+4+4+2+4+6 -> 130 | C29: =6+4+6+6+12+12+6+6+4+4+12+4+12+2+4+6+2+4+4+12+6 -> 134 | D29: =1+9+1+1+1+4 -> 17 | E29: =10200+17400+12600+15000+7200+13800+6600+6600+25200+4800+8100+22800+9600+9000+8400+4200+1600 -> 183100 | F29: =12600+9000+5400+7200+7200+5400+3600 -> 50400 | G29: =19200+22800+19200+7800+7700+11800+22800+11400 -> 122700 | H29: =E29+F29 -> 233500
A30: 45957 | B30: =6+6+6+2 -> 20 | C30: =2+6+2+2 -> 12 | E30: =7800+4200+2000 -> 14000 | F30: =5400+12600+2400 -> 20400 | H30: =E30+F30 -> 34400
A31: 45958 | B31: =6+3+12+2+24+1+1+3 -> 52 | C31: =8+1+6+1+2+2+2+6+2 -> 30 | E31: =5400+9600+4200+2400 -> 21600 | F31: =3900+7200+12000+3300+8100+5100 -> 39600 | G31: =28080 -> 28080 | H31: =E31+F31 -> 61200
A32: 45959 | B32: =3+3+1 -> 7 | C32: =2+3+4+2 -> 11 | D32: =1 -> 1 | E32: =6300+900 -> 7200 | F32: =6000+2400 -> 8400 | G32: =6960 -> 6960 | H32: =E32+F32 -> 15600
A33: 45960 | B33: =4+10+4+4+3+6 -> 31 | C33: =4+8+2+6 -> 20 | D33: =3+3 -> 6 | E33: =13200+3000 -> 16200 | F33: =4800+6000+3600+12900 -> 27300 | G33: =11700+7020 -> 18720 | H33: =E33+F33 -> 43500
A34: 45961 | B34: =6+12 -> 18 | E34: =5400+11000 -> 16400 | H34: =E34+F34 -> 16400

Sheet GASTOS NOVIEMBRE
A1: DETALLES GASTOS ENTREGADOS POR CONTRATISTA, FACTURAS "A"
K2: PAGOS
A3: FECHA | B3: ABONO | C3: RUBRO | D3: PROVEEDOR | E3: CANTIDAD | F3: DESCRIPCIÓN | G3: $ c/IVA+Ing.Br | H3: IVA | I3: 1/2IVA | J3: Perc.Ing.Bruto | K3: EFECTIVO | L3: TRANFERENCIA | M3: PEYA WALLET
A4: 45965 | B4: C | C4: DULCE DE LECHE | D4: LUZ AZUL | E4: 2 | F4: 2 POTE X 10KG DULCE DE LECHE LUZ AZUL | G4: =2*42250 -> 84500 | K4: =SUM(G4) -> 84500
A5: 45962 | B5: C | C5: PEDIDO YA | D5: PEDIDO YA | E5: 1 | F5: GASTOS DE COMICION 13-10 AL 19-10 | G5: =22662.95+4759.22+24000 -> 51422.17 | K5: 0 | M5: =G5 -> 51422.17
A6: 45969 | B6: C | C6: DULCE DE LECHE | D6: JULIA | E6: 2 | F6: 4 POTE X 10KG DULCE DE LECHE PIGUENSE | G6: =25500*2 -> 51000 | K6: =SUM(G6) -> 51000
A7: 45969 | B7: C | C7: PEDIDO YA | D7: PEDIDO YA | E7: 1 | F7: GASTOS DE COMICION 20-10 AL 26-10 | G7: =56143.31+19200+15822.1+51000 -> 142165.41 | K7: 0 | M7: =G7 -> 142165.41
A8: 45970 | B8: C | C8: CUBANITO COMUN | D8: MAXI | E8: 400 | F8: 1 CAJA X 400 CUBANITOS COMUNES ($156,00 X UNIDAD) | G8: =400*156 -> 62400 | L8: =G8 -> 62400
A9: 45970 | B9: C | C9: EXTRACCION | D9: ERICA | F9: EXTRACCION MES SEPTIEMBRE EFECTIVO | G9: 800000 | K9: 400000 | L9: 0 | M9: 400000
A10: 45970 | B10: C | C10: EXTRACCION | D10: MATIAS | F10: EXTRACCION MES SEPTIEMBRE BANCARIZADA X TRANFERENCIAS | G10: 800000 | K10: 69500 | L10: =G10-M10-K10 -> 566938.74 | M10: 163561.26
A11: 45974 | B11: C | C11: CONTADOR | D11: JORGE | E11: 1 | F11: PAGO MENSUAL JORGE | G11: 15000 | L11: =G11 -> 15000
A12: 45975 | B12: C | C12: PEDIDO YA | D12: PEDIDO YA | E12: 1 | F12: GASTOS DE COMICION 27-10 AL 02-11 | G12: =37049.82+7780.46+23000-19200 -> 48630.28 | K12: 0 | M12: =G12 -> 48630.28
A13: 45976 | B13: C | C13: CUBANITO COMUN | D13: MAXI | E13: 400 | F13: 1 CAJA X 400 CUBANITOS COMUNES ($156,00 X UNIDAD) | G13: 62400
A14: 45976 | B14: C | C14: CUBANITO BAÑADO | D14: MAXI | E14: 400 | F14: 1 CAJA X 400 CUBANITOS BAÑADOS ($358,00 X UNIDAD) | G14: 143200
A15: 45958 | B15: C | C15: CUBANITO BAÑADO | D15: MAXI | E15: 200 | F15: 1 CAJA X 200 CUBANITOS BAÑADOS ($358,00 X UNIDAD) | G15: 71100 | K15: =G13+G14+G15 -> 276700
A16: 45978 | B16: C | C16: BOLSAS | D16: Plasticos blancon | E16: 100 | F16: 100 BOLSAS NCAMISETAS DE 40X50 | G16: 2900 | K16: =G16 -> 2900
A17: 45978 | B17: C | C17: IMPUESTO | D17: ARCA | E17: 1 | F17: MONOTRIBUTO MES NOVIEMBRE | G17: 44580.74 | L17: =G17 -> 44580.74
A18: 45978 | B18: C | C18: IMPUESTO | D18: MUNICIPALIDAD | E18: 1 | F18: TASA SEGURIDAD E HIGIENE NOVIEMBRE 2025 | G18: 15103 | L18: =G18 -> 15103
A19: 45980 | B19: C | C19: DULCE DE LECHE | D19: LUZ AZUL | E19: 2 | F19: 2 POTE X 10KG DULCE DE LECHE LUZ AZUL | G19: 88300 | K19: =SUM(G19) -> 88300 | M19: =G4+G5+G6+G8+G11+G12+G13+G14+G15+G16+G17+G18+G19 -> 740536.19
A20: 45986 | B20: C | C20: PEDIDO YA | D20: PEDIDO YA | E20: 1 | F20: GASTOS DE COMICION 3-11 AL 09-11 | G20: =29489.56+10260+8347.41 -> 48096.97 | K20: 0 | M20: =G20 -> 48096.97
A21: 45987 | B21: C | C21: PLAGAS | D21: LUGONES | F21: CONTROL DE PLGAS MES OCTUBRE | G21: 16000 | L21: =G21 -> 16000
A22: 45988 | B22: C | C22: BOLSAS | D22: PAPELERA SAN LUIS | E22: 1000 | F22: 500 BOLSAS N3L+ 500 BOLSAS N4 | G22: 25000 | K22: =G22 -> 25000
A23: 45988 | B23: C | C23: BOLSAS | D23: MICRO ENVASES | E23: 1 | F23: 100 GUANTES+ BOLSAS CAMISETAS | G23: 5000 | K23: =G23 -> 5000
A24: 45990 | B24: C | C24: DULCE DE LECHE | D24: LUZ AZUL | E24: 1 | F24: 1 POTE X 10KG DULCE DE LECHE LUZ AZUL | G24: =44000 -> 44000 | K24: =SUM(G24) -> 44000
A25: 45990 | B25: C | C25: PEDIDO YA | D25: PEDIDO YA | E25: 1 | F25: GASTOS DE COMICION 10-11 AL 16-11 | G25: =41590.59+8734.02+27620 -> 77944.61 | K25: 0 | M25: =G25 -> 77944.61
A26: 45991 | B26: C | C26: CUBANITO COMUN | D26: MAXI | E26: 200 | F26: 1 CAJA X 200 CUBANITOS COMUNES ($156,00 X UNIDAD) | G26: 31200 | L26: =G26 -> 31200
A27: 45991 | B27: C | C27: CUBANITO COMUN | D27: MAXI | E27: 200 | F27: 1 CAJA X 200 CUBANITOS BAÑADOS ($358,00 X UNIDAD) | G27: 71600 | L27: =G27 -> 71600
A28: 45991 | B28: C | C28: EXTRACCION | D28: ERICA | F28: EXTRACCION MES SEPTIEMBRE EFECTIVO | G28: 350000 | K28: 0 | L28: =G28-M28 -> 106000 | M28: 244000
A29: 45991 | B29: C | C29: EXTRACCION | D29: MATIAS | F29: EXTRACCION MES SEPTIEMBRE BANCARIZADA X TRANFERENCIAS | G29: 350000 | K29: 0 | L29: 350000
G31: =G4+G5+G6+G7+G8+G11+G12+G13+G14+G15+G16+G17+G18+G19+G20+G21+G22+G23+G24+G25+G26+G27 -> 1201543.2
A53: 45930 | B53: C | C53: PEDIDO YA | D53: PEDIDO YA | E53: 1 | F53: GASTOS DE COMICION 15-9 AL 21-9 | G53: =20677+4894.54+7415.75 -> 32987.29 | K53: 0 | M53: =G53 -> 32987.29
A54: 45940 | B54: C | C54: CUBANITO COMUN | D54: MAXI | E54: 600 | F54: 1 CAJA X 600 CUBANITOS COMUNES ($156,00 X UNIDAD) | G54: =62400+31200 -> 93600 | K54: =G54 -> 93600
A55: 45943 | B55: C | C55: DULCE DE LECHE | D55: JULIA | E55: 4 | F55: 4 POTE X 10KG DULCE DE LECHE PIGUENSE | G55: =25000*4 -> 100000 | K55: =SUM(G55) -> 100000
A56: 45943 | B56: C | C56: CONTADOR | D56: JORGE | E56: 1 | F56: PAGO MENSUAL JORGE | G56: 10000 | L56: =G56 -> 10000
A57: 45941 | B57: C | C57: IMPUESTO | D57: ARCA | E57: 1 | F57: MONOTRIBUTO MES OCTUBRE | G57: 11677.6 | L57: =G57 -> 11677.6
A58: 45930 | B58: C | C58: PEDIDO YA | D58: PEDIDO YA | E58: 1 | F58: GASTOS DE COMICION 22-9 AL 28-9 | G58: =1119.23+235.04 -> 1354.27 | K58: 0 | M58: =G58 -> 1354.27
A59: 45945 | B59: C | C59: EXTRACCION | D59: ERICA | F59: EXTRACCION MES SEPTIEMBRE EFECTIVO | G59: 650000 | K59: 400000 | L59: 250000
A60: 45945 | B60: C | C60: EXTRACCION | D60: MATIAS | F60: EXTRACCION MES SEPTIEMBRE BANCARIZADA X TRANFERENCIAS | G60: 650000 | K60: 350000 | L60: 300000
A61: 45947 | B61: C | C61: PEDIDO YA | D61: PEDIDO YA | E61: 1 | F61: GASTOS DE COMICION 29-9 AL 5-10 | G61: =31291.02+4829.1+7585.22+6600 -> 50305.34 | K61: 0 | M61: =G61 -> 50305.34
A62: 45951 | B62: C | C62: PLAGAS | D62: LUGONES | F62: CONTROL DE PLGAS MES OCTUBRE | G62: 16000 | L62: =G62 -> 16000
...

Sheet VENTAS NOVIEMBRE
A1: MES:
B2: CUBANITOS | E2: METODO DE PAGO | H2: TOTAL | J2: MES NOVIEMBRE
A3: DIA | B3: COMUNES | C3: BAÑADOS | D3: OTRO | E3: EFECTIVO | F3: TRANSFERENCIA | G3: PEDIDOS YA | H3: VENTAS $
A4: 45962 | B4: =2+15+6+2+6+12+6+12+4+6 -> 71 | C4: =4+6+2+6+6+6+2+1+1+4 -> 38 | D4: 3 | E4: =6600+3600+7200+1000+3000+1000+4800 -> 27200 | F4: =13500+4200+12600+5400+18000+5400+2400 -> 61500 | G4: =19200+15600 -> 34800 | H4: =E4+F4 -> 88700 | J4: Tranferencia | K4: =SUMIF(F4:F31,">0") -> 768420
A5: 45963 | B5: =12+4+2+4+3+18+4+4+2+6+6+6+4+1+3+12 -> 91 | C5: =6+4+6+8+1+6+8+12+4+6+12+4+6+2+4+2+2+6+6 -> 105 | D5: 3 | E5: =9000+3900+16200+13200+11600+2400+11400+10800 -> 78500 | F5: =18000+8400+3000+13200+7200+14400+8400+7200+4800+12600+8400+3300+9900 -> 118800 | G5: =25400+7800 -> 33200 | H5: =E5+F5 -> 197300 | J5: efectivo | K5: =SUMIF(E4:E31,">0") -> 927900
A6: 45964 | B6: =3+4+6+4+1+6+6+1 -> 31 | C6: =2+2+6+1 -> 11 | D6: 3 | E6: =3000+600+6000+3300+5400+12600 -> 30900 | F6: =6000+5400+2100 -> 13500 | H6: =E6+F6 -> 44400 | J6: PedidosYA | K6: =SUMIF(G4:G34,">0") -> 518820
A7: 45965 | B7: =1+12 -> 13 | C7: =6+3 -> 9 | E7: =3600+900+10800 -> 15300 | F7: 7200 | H7: =E7+F7 -> 22500 | J7: TOTAL | K7: =K4+K5+K6 -> 2215140
A8: 45966 | B8: =8+8+1+8 -> 25 | C8: =4+2+2+4 -> 12 | E8: 0 | F8: =4800+7200+2400+7200+3300 -> 24900 | G8: =16200 -> 16200 | H8: =E8+F8 -> 24900
A9: 45967 | B9: =6+4+3+8+1+3 -> 25 | C9: =12+7+5+3+3+4+4+3+3 -> 44 | D9: =1+1 -> 2 | E9: =3600+3600+13200+7500 -> 27900 | F9: =14400+6000+7500+4800+4500 -> 37200 | G9: 20700 | H9: =E9+F9 -> 65100 | J9: CONSUMO CUBANITOS
A10: 45968 | B10: =4+2+6+3+12+6 -> 33 | C10: =5+2+4+4+3+12+24 -> 54 | D10: =3+3+3+3 -> 12 | E10: =2400+6600+4800+9600+9300+5400+3000+28800 -> 69900 | F10: =6000+10800 -> 16800 | G10: =7020+20520 -> 27540 | H10: =E10+F10 -> 86700 | J10: COMUNES | K10: BAÑADOS
A11: 45969 | B11: =5+6+3+1+6+1+9+4+3+4+8+6 -> 56 | C11: =3+8+3+6+6+6+13+3+2+9+4+4 -> 67 | D11: =1+3 -> 4 | E11: =12600+900+21000+1200+3300+3600+5700+8400+5400 -> 62100 | F11: =3600+9600+8100+2700+7200+7200+18900+12000 -> 69300 | G11: 5700 | H11: =E11+F11 -> 131400 | J11: =SUM(B4:B33) -> 1163 | K11: =SUM(C4:C33) -> 961
A12: 45970 | B12: =8+6+18+12+6+12+12+6+6+4+12+6+1+6+2+6 -> 123 | C12: =5+6+6+6+4+12+2+6+4+2 -> 53 | D12: 1 | E12: =6000+5400+16200+7200+12000+10800+5700+7200+10800+6600+7800 -> 95700 | F12: =7200+10800+5400+4800+14400+3300+5400 -> 51300 | G12: =15600+7800+7800+11400 -> 42600 | H12: =E12+F12 -> 147000
A13: 45971 | B13: =2+10+16+12+1 -> 41 | C13: =1+2+2+2 -> 7 | E13: =3000+9000+2400+10800 -> 25200 | F13: =11400+3300 -> 14700 | H13: =E13+F13 -> 39900
A14: 45972 | B14: =8+6+2+2+6+5+3 -> 32 | C14: =6+4+4+1+5+3 -> 23 | E14: =7200+12000+5400+4800+1800+3000+10500 -> 44700 | F14: =5400+6300 -> 11700 | H14: =E14+F14 -> 56400
A15: 45973 | B15: =3+4+3+2 -> 12 | C15: =5+8+6+3+2 -> 24 | E15: =2700+13200+6300+4200 -> 26400 | F15: =6000+7200 -> 13200 | H15: =E15+F15 -> 39600
A16: 45974 | B16: =6+2+1+6+6+6+2 -> 29 | C16: =2+1+4+6 -> 13 | E16: =5400+4200+2100+6600 -> 18300 | F16: 7020 | G16: =7020+10260 -> 17280 | H16: =E16+F16 -> 25320
A17: 45975 | B17: =5+2+4 -> 11 | C17: =3+12+4 -> 19 | E17: =8100+1800+12800 -> 22700 | F17: 14400 | H17: =E17+F17 -> 37100
A18: 45976 | B18: =6+6+15+6+4+8+6+8+2+6+12 -> 79 | C18: =6+6+4+6+10+6+6 -> 44 | D18: =3+1+3 -> 7 | E18: =8400+13500+8400+8400+10200+12600 -> 61500 | F18: =12600+7200+10800 -> 30600 | G18: =19200+19200+21600 -> 60000 | H18: =E18+F18 -> 92100
A19: 45977 | B19: =2+3+3+4+4+6+2+4+6+1+6+3+6+4+4+4+2 -> 64 | C19: =2+3+3+4+12+4+6+4+2+6+6+4+6+4+4+6+4 -> 80 | D19: =1+3+1+3+3+3 -> 14 | E19: =3000+4200+8400+14400+8400+6600+7800+8400+15600+3000+3600+3600+10200+6600 -> 103800 | F19: =6300+6000+3900+7500+8400 -> 32100 | G19: =9600+19200+20800+7600 -> 57200 | H19: =E19+F19 -> 135900
A20: 45978 | B20: =3+3+12 -> 18 | C20: 3 | D20: 1 | E20: 3900 | F20: =6300+10800 -> 17100 | H20: =E20+F20 -> 21000
A21: 45979 | B21: =12+3+3+1+24+3+6+3 -> 55 | C21: =5+3+3+2+3+3+12+8+8 -> 47 | D21: 1 | E21: =10800+3300+6300+5400+6300+14400 -> 46500 | F21: =6000+7500+2700+3600+9600+9600 -> 39000 | G21: =31200 -> 31200 | H21: =E21+F21 -> 85500
A22: 45980 | B22: =5+6+2+4+6+2 -> 25 | C22: =4+5+2+2+12 -> 25 | E22: =4800+1800+3600 -> 10200 | F22: =10500+7800+5400+4200+14400 -> 42300 | H22: =E22+F22 -> 52500
A23: 45981 | B23: =3+3 -> 6 | C23: 3 | D23: 1 | E23: =1200+2700 -> 3900 | F23: =6300 -> 6300 | H23: =E23+F23 -> 10200
A24: 45982 | B24: =12+3+2+6+4+3+6 -> 36 | C24: =4+6+8+2 -> 20 | E24: =6000+13200 -> 19200 | F24: =10800+2700+600+12600+2700+7800 -> 37200 | H24: =E24+F24 -> 56400
A25: 45983 | B25: =1+4+6 -> 11 | C25: =1+6+9+8+6+6 -> 36 | E25: 18900 | F25: =2100+7200+7200+12600 -> 29100 | G25: 15200 | H25: =E25+F25 -> 48000
A26: 45984 | B26: =18+6+1+4+6+3 -> 38 | C26: =6+6+12+4+6+2+3 -> 39 | E26: 6300 | F26: =23400+12600+7200 -> 43200 | G26: =22800+8900+9000+7800 -> 48500 | H26: =E26+F26 -> 49500
A27: 45985 | B27: =3+4+6+2+6+6+6+3+2 -> 38 | C27: =3+8+2+6+6+6+3+7+2 -> 43 | E27: =6300+13200+4200+5400+7200+11400 -> 47700 | F27: =5400+6300+4200 -> 15900 | G27: =7800+11400+7800+13300 -> 40300 | H27: =E27+F27 -> 63600
A28: 45986 | B28: =3+4 -> 7 | C28: 3 | F28: =6300+3600 -> 9900 | H28: =E28+F28 -> 9900
A29: 45987 | B29: =2+5+6+1 -> 14 | C29: =2+6+1 -> 9 | D29: 6 | E29: =1800+6900+12600+6000+2100 -> 29400 | H29: =E29+F29 -> 29400
A30: 45988 | B30: =2+4+4+6 -> 16 | C30: =4+4 -> 8 | D30: 1 | E30: =6600+8400+6000+5400 -> 26400 | H30: =E30+F30 -> 26400
A31: 45989 | B31: =10+2+6 -> 18 | C31: 2 | E31: 5400 | F31: 4200 | G31: 13000 | H31: =E31+F31 -> 9600
A32: 45990 | B32: =6+2+4+6+6+4+5+3+4+5 -> 45 | C32: =4+3+4+8+4+4 -> 27 | D32: =3+1 -> 4 | E32: =3600+5400+5400+13200+4500+5400 -> 37500 | F32: =3000+3600+6600+9300+4800+3900 -> 31200 | G32: 15400 | H32: =E32+F32 -> 68700
A33: 45991 | B33: =18+6+8+6+6+6+3+4+6+6+12+4+9+3+3 -> 100 | C33: =6+12+2+12+6+6+2+6+12+4+3+4+12+6 -> 93 | D33: =3+1+3+1 -> 8 | E33: =16200+21600+3000+12600+6000+7800+9600+6000+9200+11500+15600+7800 -> 126900 | F33: =12600+3600+19800+3000+13800+14700+3000 -> 70500 | G33: 40000 | H33: =E33+F33 -> 197400
H34: =E34+F34 -> 0

Sheet GASTOS DICIEMBRE
A1: DETALLES GASTOS ENTREGADOS POR CONTRATISTA, FACTURAS "A"
K2: PAGOS
A3: FECHA | B3: ABONO | C3: RUBRO | D3: PROVEEDOR | E3: CANTIDAD | F3: DESCRIPCIÓN | G3: $ c/IVA+Ing.Br | H3: IVA | I3: 1/2IVA | J3: Perc.Ing.Bruto | K3: EFECTIVO | L3: TRANFERENCIA | M3: PEYA WALLET
A4: 45992 | B4: C | C4: CUBANITO COMUN | D4: MAXI | E4: 200 | F4: 1 CAJA X 400 CUBANITOS COMUNES ($168,50 X UNIDAD) | G4: =168.5*E4 -> 33700
A5: 45992 | B5: C | C5: CUBANITO BAÑADO | D5: MAXI | E5: 200 | F5: 1 CAJA X 400 CUBANITOS BAÑADOS ($490,00 X UNIDAD) | G5: =490*E5 -> 98000 | K5: =G4+G5 -> 131700
A6: 45992 | B6: C | C6: BOLSAS | D6: PLASTICOS BLANCOS | E6: 400 | F6: 400 BOLSAS GARRAPIÑADAS | G6: 6470 | L6: =G6 -> 6470
A7: 45995 | B7: C | C7: DULCE DE LECHE | D7: LUZ AZUL | E7: 1 | F7: 1 POTE X 10KG DULCE DE LECHE LUZ AZUL (44500) | G7: 44500 | K7: =G7 -> 44500 | L7: 0
A8: 46000 | B8: C | C8: CUBANITO COMUN | D8: MAXI | E8: 200 | F8: 1 CAJA X 400 CUBANITOS COMUNES ($168,50 X UNIDAD) | G8: =168.5*E8 -> 33700 | K8: =G8 -> 33700
A9: 46020 | B9: C | C9: PEDIDO YA | D9: PEDIDO YA | E9: 1 | F9: GASTOS DE COMICION 17-11 AL 23-11 | G9: =21827+2559.04+5121.07 -> 29507.11 | K9: 0 | M9: =G9 -> 29507.11
A10: 46000 | B10: C | C10: DULCE DE LECHE | D10: LUZ AZUL | E10: 1 | F10: 1 POTE X 10KG DULCE DE LECHE LUZ AZUL (44500) | G10: 44200 | K10: =G10 -> 44200 | L10: 0
A11: 46020 | B11: C | C11: PEDIDO YA | D11: PEDIDO YA | E11: 1 | F11: GASTOS DE COMICION 24-11 AL 30-11 | G11: =29688.3+5539.28+22900-9239.74 -> 48887.84 | K11: 0 | M11: =G11 -> 48887.84
A12: 46000 | B12: C | C12: CUBANITO COMUN | D12: MAXI | E12: 200 | F12: 1 CAJA X 200 CUBANITOS BAÑADOS ($490,00 X UNIDAD) | G12: 98000 | K12: =G12 -> 98000
A13: 46004 | B13: C | C13: CONTADOR | D13: JORGE | E13: 1 | F13: PAGO MENSUAL JORGE | G13: 15000 | L13: =G13 -> 15000
